const x = '10'

try {
    x = 4
} catch (error) {
    console.log(error)
}

console.log('continuação do código')